Workbook

Sheet 代收代辦
A1: 桃園市龍潭區石門國民小學粘貼憑證用紙
A2: 所屬年度: | B2: 112 | P2: 簽證 | R2: 號
A3: 憑證編號 | B3: 預 算 科 目 | G3: 金 額 | P3: 用 途 說 明 | T3: 說明
B4: 應付代收款 | H4: 千 萬 | I4: 百 萬 | J4: 十 萬 | K4: 萬 | L4: 千 | M4: 百 | N4: 十 | O4: 元 | P4: =IF(ISBLANK(J15),"",J15) | T4: 1.【金額】及【用途說明】為自動帶入，無須填寫。 2.【預算科目】為下拉式選單。
B5: B20001校務發展經費-校園修繕及專案建設經費 | H5: =IF(LEN($G$31)<8,IF($G$31=0,0,"－"),MID($G$31,LEN($G$31)-7,1)) | I5: =IF(LEN($G$31)<7,IF($G$31=0,0,"－"),MID($G$31,LEN($G$31)-6,1)) | J5: =IF(LEN($G$31)<6,IF($G$31=0,0,"－"),MID($G$31,LEN($G$31)-5,1)) | K5: =IF(LEN($G$31)<5,IF($G$31=0,0,"－"),MID($G$31,LEN($G$31)-4,1)) | L5: =IF(LEN($G$31)<4,IF($G$31=0,0,"－"),MID($G$31,LEN($G$31)-3,1)) | M5: =IF(LEN($G$31)<3,IF($G$31=0,0,"－"),MID($G$31,LEN($G$31)-2,1)) | N5: =IF(LEN($G$31)<2,IF($G$31=0,0,"－"),MID($G$31,LEN($G$31)-1,1)) | O5: =IF(LEN($G$31)<1,IF($G$31=0,0,"－"),MID($G$31,LEN($G$31)-0,1))
A7: 經辦單位 | D7: 驗收或證明、保管 | G7: 總務處 | I7: 登記(所得、物品、財產) | L7: 會計單位 | P7: 機關長官或 授權代簽人
A8: 經辦人 | I8: 所得 | T8: 1.經辦單位請承辦人及處室主管章，處室主管在虛線處章。 2. 登記(所得、物品、財產 )請書寫物品、財產帳編號。 3.採購案請會辦總務處核章。
A9: 經辦主管 | I9: 物品、財產
A10: （ 憑 證 黏 貼 線 ）
A12: 動 支 經 費 請 示 單 | O12: □受款人 □發票(或收據)開立廠商 □匯入帳戶 □＿＿＿＿＿墊付 □扣抵罰賠款 元 □轉保固金 元 □代扣稅款 元 □其他(請列舉並標示金額) | T12: 說明
A13: 單位別： | B13: 總務處 | F13: =YEAR(TODAY())-1911 | I13: 年 | J13: 5 | K13: 月 | L13: 12 | M13: 日 | T13: 1.【單位別】為下拉式選單。 2.數量、單價欄位填入後會自動代出金額、合計。 3.【用途說明】欄位填入後，會自動帶入上方對應欄位。
A14: 名稱及規格 | C14: 數量 | E14: 單 價 | G14: 金 額 | J14: 用 途 說 明
A15: 建置教室數位互動教學設備採購案(11007)履保金 | C15: 1 | E15: 116000 | G15: =ROUND(C15*E15,0) | J15: 建置教室數位互動教學設備採購案(11007)履保金
G17: =ROUND(C17*E17,0)
G19: =ROUND(C19*E19,0) | J19: 零用金支付
G21: =ROUND(C21*E21,0)
J22: 總 務 處 簽 擬 | O22: 附件： □發票 張 □收據 張 (並至財政部稅務入口網之 營業登記資料公示查詢) □動支經費請示單或核准 辦理文件 張 □驗收報告 張 □合約書 份 □其他文件(需註明文件 名稱、份數)
G23: =ROUND(C23*E23,0) | J23: 擬交
J24: 承辦
G25: =ROUND(C25*E25,0) | J25: 經辦人：
G27: =ROUND(C27*E27,0) | J27: 主 任：
G29: =ROUND(C29*E29,0) | J29: 預算數：
J30: 已支數：
A31: 合 計 | G31: =SUM(G15:I30) | J31: 餘 額： | L31: =IF(M29="","",M29-G31-M30)
A33: 申 請 單 位 | F33: 會 計 室 | K33: 校 長 | P33: 財產或物品登記訖
A34: 經辦人 | P34: □非消耗品 □財產
A35: 單位主管

Sheet 預算內
A1: 桃園市龍潭區石門國民小學粘貼憑證用紙
A2: 所屬年度: | B2: 113 | O2: 簽證 | Q2: 號
A3: 憑證編號 | D3: 預 算 科 目 | G3: 金 額 | O3: 用 途 說 明 | S3: 說明
B4: 材料及用品費 | G4: 千 萬 | H4: 百 萬 | I4: 十 萬 | J4: 萬 | K4: 千 | L4: 百 | M4: 十 | N4: 元 | O4: =I15 | S4: 1.【金額】及【用途說明】為自動帶入，無須填寫。 2.【預算科目】為下拉式選單。
B5: 255機械及設備修護費 | G5: =IF(LEN($G$31)<8,IF($G$31=0,0,"－"),MID($G$31,LEN($G$31)-7,1)) | H5: =IF(LEN($G$31)<7,IF($G$31=0,0,"－"),MID($G$31,LEN($G$31)-6,1)) | I5: =IF(LEN($G$31)<6,IF($G$31=0,0,"－"),MID($G$31,LEN($G$31)-5,1)) | J5: =IF(LEN($G$31)<5,IF($G$31=0,0,"－"),MID($G$31,LEN($G$31)-4,1)) | K5: =IF(LEN($G$31)<4,IF($G$31=0,0,"－"),MID($G$31,LEN($G$31)-3,1)) | L5: =IF(LEN($G$31)<3,IF($G$31=0,0,"－"),MID($G$31,LEN($G$31)-2,1)) | M5: =IF(LEN($G$31)<2,IF($G$31=0,0,"－"),MID($G$31,LEN($G$31)-1,1)) | N5: =IF(LEN($G$31)<1,IF($G$31=0,"","－"),MID($G$31,LEN($G$31),1))
A7: 經辦單位 | C7: 驗收或證明、保管 | F7: 總務處 | H7: 登記(所得、物品、財產) | K7: 會計單位 | O7: 機關長官或 授權代簽人 | S7: 1.經辦單位請承辦人及處室主管章，處室主管在虛線處章。 2.登記(所得、物品、財產 )請書寫物品、財產帳編號。 3.採購案請會辦總務處核章。
A8: 經辦人 | H8: 所得
A9: 經辦主管 | H9: 物品、財產
A10: （ 憑 證 黏 貼 線 ）
A12: 動 支 經 費 請 示 單 | N12: □受款人 □發票(或收據)開立廠商 □詳如受款人清單 □ 墊付 □扣抵罰賠款 元 □轉保固金 元 □代扣稅款 元 □其他(請列舉並標示金額) | S12: 說明
A13: 單位別： | B13: 教務處 | F13: =YEAR(TODAY())-1911 | H13: 年 | I13: 1 | J13: 月 | K13: 14 | L13: 日 | S13: 1.【單位別】為下拉式選單。 2.數量、單價欄位填入後會自動代出金額、合計。 3.【用途說明】欄位填入後，會自動帶入上方對應欄位。
A14: 名 稱 及 規 格 | C14: 數量 | E14: 單 價 | G14: 金 額 | I14: 用 途 說 明
A15: 【Kingston 金士頓】KC600 SATA-3 256GB SSD 固態硬碟(★SKC600/256G) | C15: 1 | E15: 780 | G15: =ROUND(C15*E15,0) | I15: 行政人員電腦備份移機專用快速開機硬碟
G17: =ROUND(C17*E17,0)
G19: =ROUND(C19*E19,0) | I19: 零用金支付
G21: =ROUND(C21*E21,0)
I22: 總 務 處 簽 擬 | N22: 附件： □發票 張 □收據 張 (並至財政部稅務入口網之 營業登記資料公示查詢) □動支經費請示單或核准 辦理文件 張 □驗收報告 張 □合約書 份 □其他文件(需註明文件 名稱、份數)
G23: =ROUND(C23*E23,0) | I23: 擬交
I24: 承辦
G25: =ROUND(C25*E25,0) | I25: 經辦人：
G27: =ROUND(C27*E27,0) | I27: 主 任：
G29: =ROUND(C29*E29,0) | I29: 預算數：
I30: 已支數：
A31: 合 計 | G31: =SUM(G15:H30) | I31: 餘 額： | K31: =IF(L29="","",L29-G31-L30)
A33: 申 請 單 位 | F33: 會 計 室 | I33: 校 長 | O33: 財產或物品登記訖
A34: 經辦人 | O34: □非消耗品 □財產
A35: 單位主管

Sheet 預算外選單資料來源
A1: 一級科目 | B1: =[1]預算外選單資料來源!B1 | C1: =[1]預算外選單資料來源!C1 | D1: =[1]預算外選單資料來源!D1 | E1: =[1]預算外選單資料來源!E1 | F1: =[1]預算外選單資料來源!F1
A2: 應付代收款 | B2: =[1]預算外選單資料來源!$B$2 | C2: X00001壓克力籃球場整修工程-工展營造有限公司 | D2: =[1]預算外選單資料來源!D2 | E2: =[1]預算外選單資料來源!E2 | F2: =[1]預算外選單資料來源!F2
A3: 押標金 | B3: =[1]預算外選單資料來源!B3 | C3: =[1]預算外選單資料來源!C3 | D3: =[1]預算外選單資料來源!D3 | E3: =[1]預算外選單資料來源!E3 | F3: =[1]預算外選單資料來源!F3
A4: 履約保證金 | B4: =[1]預算外選單資料來源!B4 | C4: =[1]預算外選單資料來源!C4 | D4: =[1]預算外選單資料來源!D4 | E4: =[1]預算外選單資料來源!E4 | F4: =[1]預算外選單資料來源!F4
A5: 保固金 | B5: =[1]預算外選單資料來源!B5 | C5: =[1]預算外選單資料來源!C5 | D5: =[1]預算外選單資料來源!D5 | E5: =[1]預算外選單資料來源!E5 | F5: =[1]預算外選單資料來源!F5
A6: 暫收及待結轉帳項 | B6: =[1]預算外選單資料來源!B6 | C6: =[1]預算外選單資料來源!C6 | D6: =[1]預算外選單資料來源!D6 | E6: =[1]預算外選單資料來源!E6 | F6: =[1]預算外選單資料來源!F6
A7: 應付保證品 | B7: =[1]預算外選單資料來源!B7 | C7: =[1]預算外選單資料來源!C7 | D7: =[1]預算外選單資料來源!D7 | E7: =[1]預算外選單資料來源!E7 | F7: =[1]預算外選單資料來源!F7
B8: =[1]預算外選單資料來源!B8 | C8: =[1]預算外選單資料來源!C8 | D8: =[1]預算外選單資料來源!D8 | E8: =[1]預算外選單資料來源!E8 | F8: =[1]預算外選單資料來源!F8
B9: =[1]預算外選單資料來源!B9 | C9: =[1]預算外選單資料來源!C9 | D9: =[1]預算外選單資料來源!D9 | E9: =[1]預算外選單資料來源!E9 | F9: =[1]預算外選單資料來源!F9
B10: =[1]預算外選單資料來源!B10 | C10: =[1]預算外選單資料來源!C10 | D10: =[1]預算外選單資料來源!D10 | E10: =[1]預算外選單資料來源!E10 | F10: =[1]預算外選單資料來源!F10
B11: =[1]預算外選單資料來源!B11 | C11: =[1]預算外選單資料來源!C11 | D11: =[1]預算外選單資料來源!D11 | E11: =[1]預算外選單資料來源!E11 | F11: =[1]預算外選單資料來源!F11
B12: =[1]預算外選單資料來源!B12 | C12: =[1]預算外選單資料來源!C12 | D12: =[1]預算外選單資料來源!D12 | E12: =[1]預算外選單資料來源!E12 | F12: =[1]預算外選單資料來源!F12
B13: =[1]預算外選單資料來源!B13 | C13: =[1]預算外選單資料來源!C13 | D13: =[1]預算外選單資料來源!D13 | E13: =[1]預算外選單資料來源!E13 | F13: =[1]預算外選單資料來源!F13
B14: =[1]預算外選單資料來源!B14 | C14: =[1]預算外選單資料來源!C14 | D14: =[1]預算外選單資料來源!D14 | E14: =[1]預算外選單資料來源!E14 | F14: =[1]預算外選單資料來源!F14
B15: =[1]預算外選單資料來源!B15 | C15: =[1]預算外選單資料來源!C15 | D15: =[1]預算外選單資料來源!D15 | E15: =[1]預算外選單資料來源!E15 | F15: =[1]預算外選單資料來源!F15
B16: =[1]預算外選單資料來源!B16 | C16: =[1]預算外選單資料來源!C16 | D16: =[1]預算外選單資料來源!D16 | E16: =[1]預算外選單資料來源!E16 | F16: =[1]預算外選單資料來源!F16
B17: =[1]預算外選單資料來源!B17 | C17: =[1]預算外選單資料來源!C17 | D17: =[1]預算外選單資料來源!D17 | E17: =[1]預算外選單資料來源!E17 | F17: =[1]預算外選單資料來源!F17
B18: =[1]預算外選單資料來源!B18 | C18: =[1]預算外選單資料來源!C18 | D18: =[1]預算外選單資料來源!D18 | E18: =[1]預算外選單資料來源!E18 | F18: =[1]預算外選單資料來源!F18
B19: =[1]預算外選單資料來源!B19 | C19: =[1]預算外選單資料來源!C19 | D19: =[1]預算外選單資料來源!D19 | E19: =[1]預算外選單資料來源!E19 | F19: =[1]預算外選單資料來源!F19
... B108: =[1]預算外選單資料來源!B108 | C108: =[1]預算外選單資料來源!C108 | D108: =[1]預算外選單資料來源!D108 | E108: =[1]預算外選單資料來源!E108 | F108: =[1]預算外選單資料來源!F108
B109: G00001關懷動物生命教育 | C109: =[1]預算外選單資料來源!C109 | D109: =[1]預算外選單資料來源!D109 | E109: =[1]預算外選單資料來源!E109 | F109: =[1]預算外選單資料來源!F109
B110: =[1]預算外選單資料來源!B110 | C110: =[1]預算外選單資料來源!C110 | D110: =[1]預算外選單資料來源!D110 | E110: =[1]預算外選單資料來源!E110 | F110: =[1]預算外選單資料來源!F110
B111: =[1]預算外選單資料來源!B111 | C111: =[1]預算外選單資料來源!C111 | D111: =[1]預算外選單資料來源!D111 | E111: =[1]預算外選單資料來源!E111 | F111: =[1]預算外選單資料來源!F111
B112: =[1]預算外選單資料來源!B112 | C112: =[1]預算外選單資料來源!C112 | D112: =[1]預算外選單資料來源!D112 | E112: =[1]預算外選單資料來源!E112 | F112: =[1]預算外選單資料來源!F112
B113: =[1]預算外選單資料來源!B113 | C113: =[1]預算外選單資料來源!C113 | D113: =[1]預算外選單資料來源!D113 | E113: =[1]預算外選單資料來源!E113 | F113: =[1]預算外選單資料來源!F113
B114: =[1]預算外選單資料來源!B114 | C114: =[1]預算外選單資料來源!C114 | D114: =[1]預算外選單資料來源!D114 | E114: =[1]預算外選單資料來源!E114 | F114: =[1]預算外選單資料來源!F114
B115: =[1]預算外選單資料來源!B115 | C115: =[1]預算外選單資料來源!C115 | D115: =[1]預算外選單資料來源!D115 | E115: =[1]預算外選單資料來源!E115 | F115: =[1]預算外選單資料來源!F115
B116: =[1]預算外選單資料來源!B116 | C116: =[1]預算外選單資料來源!C116 | D116: =[1]預算外選單資料來源!D116 | E116: =[1]預算外選單資料來源!E116 | F116: =[1]預算外選單資料來源!F116
B117: =[1]預算外選單資料來源!B117 | C117: =[1]預算外選單資料來源!C117 | D117: =[1]預算外選單資料來源!D117 | E117: =[1]預算外選單資料來源!E117 | F117: =[1]預算外選單資料來源!F117
B118: =[1]預算外選單資料來源!B118 | C118: =[1]預算外選單資料來源!C118 | D118: =[1]預算外選單資料來源!D118 | E118: =[1]預算外選單資料來源!E118 | F118: =[1]預算外選單資料來源!F118
B119: =[1]預算外選單資料來源!B119 | C119: =[1]預算外選單資料來源!C119 | D119: =[1]預算外選單資料來源!D119 | E119: =[1]預算外選單資料來源!E119 | F119: =[1]預算外選單資料來源!F119
B120: =[1]預算外選單資料來源!B120 | C120: =[1]預算外選單資料來源!C120 | D120: =[1]預算外選單資料來源!D120 | E120: =[1]預算外選單資料來源!E120 | F120: =[1]預算外選單資料來源!F120
B121: =[1]預算外選單資料來源!B121 | C121: =[1]預算外選單資料來源!C121 | D121: =[1]預算外選單資料來源!D121 | E121: =[1]預算外選單資料來源!E121 | F121: =[1]預算外選單資料來源!F121
... B126: =[1]預算外選單資料來源!B126 | C126: =[1]預算外選單資料來源!C126 | D126: =[1]預算外選單資料來源!D126 | E126: =[1]預算外選單資料來源!E126 | F126: =[1]預算外選單資料來源!F126
B127: H00003 原住民族語教學支援工作人員交通費 | C127: =[1]預算外選單資料來源!C127 | D127: =[1]預算外選單資料來源!D127 | E127: =[1]預算外選單資料來源!E127 | F127: =[1]預算外選單資料來源!F127
B128: =[1]預算外選單資料來源!B128 | C128: =[1]預算外選單資料來源!C128 | D128: =[1]預算外選單資料來源!D128 | E128: =[1]預算外選單資料來源!E128 | F128: =[1]預算外選單資料來源!F128
B129: =[1]預算外選單資料來源!B129 | C129: =[1]預算外選單資料來源!C129 | D129: =[1]預算外選單資料來源!D129 | E129: =[1]預算外選單資料來源!E129 | F129: =[1]預算外選單資料來源!F129
B130: =[1]預算外選單資料來源!B130 | C130: =[1]預算外選單資料來源!C130 | D130: =[1]預算外選單資料來源!D130 | E130: =[1]預算外選單資料來源!E130 | F130: =[1]預算外選單資料來源!F130
B131: =[1]預算外選單資料來源!B131 | C131: =[1]預算外選單資料來源!C131 | D131: =[1]預算外選單資料來源!D131 | E131: =[1]預算外選單資料來源!E131 | F131: =[1]預算外選單資料來源!F131
B132: =[1]預算外選單資料來源!B132 | C132: =[1]預算外選單資料來源!C132 | D132: =[1]預算外選單資料來源!D132 | E132: =[1]預算外選單資料來源!E132 | F132: =[1]預算外選單資料來源!F132
...

Sheet 預算內選單資料來源
A1: 預算科目 | B1: =[1]預算內選單資料來源!B1 | C1: =[1]預算內選單資料來源!C1 | D1: =[1]預算內選單資料來源!D1 | E1: =[1]預算內選單資料來源!E1 | F1: =[1]預算內選單資料來源!F1 | G1: =[1]預算內選單資料來源!G1 | H1: =[1]預算內選單資料來源!H1 | I1: =[1]預算內選單資料來源!I1 | ... L1: =[1]預算內選單資料來源!L1
A2: 用人費用 | B2: =[1]預算內選單資料來源!B2 | C2: =[1]預算內選單資料來源!C2 | D2: =[1]預算內選單資料來源!D2 | E2: =[1]預算內選單資料來源!E2 | F2: =[1]預算內選單資料來源!F2 | G2: =[1]預算內選單資料來源!G2 | H2: =[1]預算內選單資料來源!H2 | I2: =[1]預算內選單資料來源!I2 | ... L2: =[1]預算內選單資料來源!L2
A3: 服務費用 | B3: =[1]預算內選單資料來源!B3 | C3: =[1]預算內選單資料來源!C3 | D3: =[1]預算內選單資料來源!D3 | E3: =[1]預算內選單資料來源!E3 | F3: =[1]預算內選單資料來源!F3 | G3: =[1]預算內選單資料來源!G3 | H3: =[1]預算內選單資料來源!H3 | I3: =[1]預算內選單資料來源!I3 | ... L3: =[1]預算內選單資料來源!L3
A4: 材料及用品費 | B4: =[1]預算內選單資料來源!B4 | C4: =[1]預算內選單資料來源!C4 | D4: =[1]預算內選單資料來源!D4 | E4: =[1]預算內選單資料來源!E4 | F4: =[1]預算內選單資料來源!F4 | G4: =[1]預算內選單資料來源!G4 | H4: =[1]預算內選單資料來源!H4 | I4: =[1]預算內選單資料來源!I4 | ... L4: =[1]預算內選單資料來源!L4
A5: 租金、償債與利息 | B5: =[1]預算內選單資料來源!B5 | C5: =[1]預算內選單資料來源!C5 | D5: =[1]預算內選單資料來源!D5 | E5: =[1]預算內選單資料來源!E5 | F5: =[1]預算內選單資料來源!F5 | G5: =[1]預算內選單資料來源!G5 | H5: =[1]預算內選單資料來源!H5 | I5: =[1]預算內選單資料來源!I5 | ... L5: =[1]預算內選單資料來源!L5
A6: 稅捐及規費 | B6: =[1]預算內選單資料來源!B6 | C6: =[1]預算內選單資料來源!C6 | D6: =[1]預算內選單資料來源!D6 | E6: =[1]預算內選單資料來源!E6 | F6: =[1]預算內選單資料來源!F6 | G6: =[1]預算內選單資料來源!G6 | H6: =[1]預算內選單資料來源!H6 | I6: =[1]預算內選單資料來源!I6 | ... L6: =[1]預算內選單資料來源!L6
A7: 會費、捐助、補助、分攤、照護、救濟與交流活動費 | B7: =[1]預算內選單資料來源!B7 | C7: =[1]預算內選單資料來源!C7 | D7: =[1]預算內選單資料來源!D7 | E7: =[1]預算內選單資料來源!E7 | F7: =[1]預算內選單資料來源!F7 | G7: =[1]預算內選單資料來源!G7 | H7: =[1]預算內選單資料來源!H7 | I7: =[1]預算內選單資料來源!I7 | ... L7: =[1]預算內選單資料來源!L7
A8: 其他 | B8: =[1]預算內選單資料來源!B8 | C8: =[1]預算內選單資料來源!C8 | D8: =[1]預算內選單資料來源!D8 | E8: =[1]預算內選單資料來源!E8 | F8: =[1]預算內選單資料來源!F8 | G8: =[1]預算內選單資料來源!G8 | H8: =[1]預算內選單資料來源!H8 | I8: =[1]預算內選單資料來源!I8 | ... L8: =[1]預算內選單資料來源!L8
A9: 營建及修建工程 | B9: =[1]預算內選單資料來源!B9 | C9: =[1]預算內選單資料來源!C9 | D9: =[1]預算內選單資料來源!D9 | E9: =[1]預算內選單資料來源!E9 | F9: =[1]預算內選單資料來源!F9 | G9: =[1]預算內選單資料來源!G9 | H9: =[1]預算內選單資料來源!H9 | I9: =[1]預算內選單資料來源!I9 | ... L9: =[1]預算內選單資料來源!L9
A10: 交通及運輸設備 | B10: =[1]預算內選單資料來源!B10 | C10: =[1]預算內選單資料來源!C10 | D10: =[1]預算內選單資料來源!D10 | E10: =[1]預算內選單資料來源!E10 | F10: =[1]預算內選單資料來源!F10 | G10: =[1]預算內選單資料來源!G10 | H10: =[1]預算內選單資料來源!H10 | I10: =[1]預算內選單資料來源!I10 | ... L10: =[1]預算內選單資料來源!L10
A11: 其他設備 | B11: =[1]預算內選單資料來源!B11 | C11: =[1]預算內選單資料來源!C11 | D11: =[1]預算內選單資料來源!D11 | E11: =[1]預算內選單資料來源!E11 | F11: =[1]預算內選單資料來源!F11 | G11: =[1]預算內選單資料來源!G11 | H11: =[1]預算內選單資料來源!H11 | I11: =[1]預算內選單資料來源!I11 | ... L11: =[1]預算內選單資料來源!L11
A12: 無形資產 | B12: =[1]預算內選單資料來源!B12 | C12: =[1]預算內選單資料來源!C12 | D12: =[1]預算內選單資料來源!D12 | E12: =[1]預算內選單資料來源!E12 | F12: =[1]預算內選單資料來源!F12 | G12: =[1]預算內選單資料來源!G12 | H12: =[1]預算內選單資料來源!H12 | I12: =[1]預算內選單資料來源!I12 | ... L12: =[1]預算內選單資料來源!L12
A13: =[1]預算內選單資料來源!A13 | B13: =[1]預算內選單資料來源!B13 | C13: =[1]預算內選單資料來源!C13 | D13: =[1]預算內選單資料來源!D13 | E13: =[1]預算內選單資料來源!E13 | F13: =[1]預算內選單資料來源!F13 | G13: =[1]預算內選單資料來源!G13 | H13: =[1]預算內選單資料來源!H13 | ... L13: =[1]預算內選單資料來源!L13
A14: =[1]預算內選單資料來源!A14 | B14: =[1]預算內選單資料來源!B14 | C14: =[1]預算內選單資料來源!C14 | D14: =[1]預算內選單資料來源!D14 | E14: =[1]預算內選單資料來源!E14 | F14: =[1]預算內選單資料來源!F14 | G14: =[1]預算內選單資料來源!G14 | H14: =[1]預算內選單資料來源!H14 | ... L14: =[1]預算內選單資料來源!L14
A15: =[1]預算內選單資料來源!A15 | B15: =[1]預算內選單資料來源!B15 | C15: =[1]預算內選單資料來源!C15 | D15: =[1]預算內選單資料來源!D15 | E15: =[1]預算內選單資料來源!E15 | F15: =[1]預算內選單資料來源!F15 | G15: =[1]預算內選單資料來源!G15 | H15: =[1]預算內選單資料來源!H15 | ... L15: =[1]預算內選單資料來源!L15
A16: =[1]預算內選單資料來源!A16 | B16: =[1]預算內選單資料來源!B16 | C16: =[1]預算內選單資料來源!C16 | D16: =[1]預算內選單資料來源!D16 | E16: =[1]預算內選單資料來源!E16 | F16: =[1]預算內選單資料來源!F16 | G16: =[1]預算內選單資料來源!G16 | H16: =[1]預算內選單資料來源!H16 | ... L16: =[1]預算內選單資料來源!L16
A17: =[1]預算內選單資料來源!A17 | B17: =[1]預算內選單資料來源!B17 | C17: =[1]預算內選單資料來源!C17 | D17: =[1]預算內選單資料來源!D17 | E17: =[1]預算內選單資料來源!E17 | F17: =[1]預算內選單資料來源!F17 | G17: =[1]預算內選單資料來源!G17 | H17: =[1]預算內選單資料來源!H17 | ... L17: =[1]預算內選單資料來源!L17
A18: =[1]預算內選單資料來源!A18 | B18: =[1]預算內選單資料來源!B18 | C18: =[1]預算內選單資料來源!C18 | D18: =[1]預算內選單資料來源!D18 | E18: =[1]預算內選單資料來源!E18 | F18: =[1]預算內選單資料來源!F18 | G18: =[1]預算內選單資料來源!G18 | H18: =[1]預算內選單資料來源!H18 | ... L18: =[1]預算內選單資料來源!L18
A19: =[1]預算內選單資料來源!A19 | B19: =[1]預算內選單資料來源!B19 | C19: =[1]預算內選單資料來源!C19 | D19: =[1]預算內選單資料來源!D19 | E19: =[1]預算內選單資料來源!E19 | F19: =[1]預算內選單資料來源!F19 | G19: =[1]預算內選單資料來源!G19 | H19: =[1]預算內選單資料來源!H19 | ... L19: =[1]預算內選單資料來源!L19
A20: =[1]預算內選單資料來源!A20 | B20: =[1]預算內選單資料來源!B20 | C20: =[1]預算內選單資料來源!C20 | D20: =[1]預算內選單資料來源!D20 | E20: =[1]預算內選單資料來源!E20 | F20: =[1]預算內選單資料來源!F20 | G20: =[1]預算內選單資料來源!G20 | H20: =[1]預算內選單資料來源!H20 | ... L20: =[1]預算內選單資料來源!L20
A21: =[1]預算內選單資料來源!A21 | B21: =[1]預算內選單資料來源!B21 | C21: =[1]預算內選單資料來源!C21 | D21: =[1]預算內選單資料來源!D21 | E21: =[1]預算內選單資料來源!E21 | F21: =[1]預算內選單資料來源!F21 | G21: =[1]預算內選單資料來源!G21 | H21: =[1]預算內選單資料來源!H21 | ... L21: =[1]預算內選單資料來源!L21
A22: =[1]預算內選單資料來源!A22 | B22: =[1]預算內選單資料來源!B22 | C22: =[1]預算內選單資料來源!C22 | D22: =[1]預算內選單資料來源!D22 | E22: =[1]預算內選單資料來源!E22 | F22: =[1]預算內選單資料來源!F22 | G22: =[1]預算內選單資料來源!G22 | H22: =[1]預算內選單資料來源!H22 | ... L22: =[1]預算內選單資料來源!L22
A23: =[1]預算內選單資料來源!A23 | B23: =[1]預算內選單資料來源!B23 | C23: =[1]預算內選單資料來源!C23 | D23: =[1]預算內選單資料來源!D23 | E23: =[1]預算內選單資料來源!E23 | F23: =[1]預算內選單資料來源!F23 | G23: =[1]預算內選單資料來源!G23 | H23: =[1]預算內選單資料來源!H23 | ... L23: =[1]預算內選單資料來源!L23
A24: =[1]預算內選單資料來源!A24 | B24: =[1]預算內選單資料來源!B24 | C24: =[1]預算內選單資料來源!C24 | D24: =[1]預算內選單資料來源!D24 | E24: =[1]預算內選單資料來源!E24 | F24: =[1]預算內選單資料來源!F24 | G24: =[1]預算內選單資料來源!G24 | H24: =[1]預算內選單資料來源!H24 | ... L24: =[1]預算內選單資料來源!L24
... A400: =[1]預算內選單資料來源!A400 | B400: =[1]預算內選單資料來源!B400 | C400: =[1]預算內選單資料來源!C400 | D400: =[1]預算內選單資料來源!D400 | E400: =[1]預算內選單資料來源!E400 | F400: =[1]預算內選單資料來源!F400 | G400: =[1]預算內選單資料來源!G400 | H400: =[1]預算內選單資料來源!H400 | ... L400: =[1]預算內選單資料來源!L400
A401: =[1]預算內選單資料來源!A401 | B401: =[1]預算內選單資料來源!B401
A402: =[1]預算內選單資料來源!A402 | B402: =[1]預算內選單資料來源!B402
A403: =[1]預算內選單資料來源!A403 | B403: =[1]預算內選單資料來源!B403
A404: =[1]預算內選單資料來源!A404 | B404: =[1]預算內選單資料來源!B404
A405: =[1]預算內選單資料來源!A405 | B405: =[1]預算內選單資料來源!B405
A406: =[1]預算內選單資料來源!A406 | B406: =[1]預算內選單資料來源!B406
A407: =[1]預算內選單資料來源!A407 | B407: =[1]預算內選單資料來源!B407
A408: =[1]預算內選單資料來源!A408 | B408: =[1]預算內選單資料來源!B408
A409: =[1]預算內選單資料來源!A409 | B409: =[1]預算內選單資料來源!B409
A410: =[1]預算內選單資料來源!A410 | B410: =[1]預算內選單資料來源!B410
A411: =[1]預算內選單資料來源!A411 | B411: =[1]預算內選單資料來源!B411
A412: =[1]預算內選單資料來源!A412 | B412: =[1]預算內選單資料來源!B412
... A693: =[1]預算內選單資料來源!A693 | B693: =[1]預算內選單資料來源!B693

Sheet 共同選單資料來源
A1: 單位別
A2: 總務處
A3: 教務處
A4: 學務處
A5: 輔導室
A6: 人事室
A7: 會計室
A8: 出納
A9: 午餐秘書
A10: 幼兒園
